<mujoco model="swimmer_position">
    <compiler angle="degree" coordinate="local" inertiafromgeom="true"/>

    <!--    Ethylene Glycol                                     absolute/dynamic   -->
    <option collision="predefined" density="1097" timestep="0.01" viscosity="0.016"/>

    <default>
        <geom conaffinity="1" condim="1" contype="1" material="geom" rgba="0.8 0.6 .4 1"/>
        <default class="mid">
            <site pos="-0.05 0 0" size="0.01"/>
        </default>
        <default class="joint_mark">
            <site pos="0 0 0" size="0.012"/>
        </default>
        <default class="j">
            <joint axis="0 0 1" limited="true" pos="0 0 0" range="-90 90" type="hinge" armature='0.01' damping="0.01" stiffness="0"/>
        </default>
        <default class="g">
            <geom density="1000" fromto="0 0 0 -0.1 0 0" size="0.01" type="capsule"/>
        </default>
    </default>
    <asset>
        <texture builtin="gradient" height="100" rgb1="1 1 1" rgb2="0 0 0" type="skybox" width="100"/>
        <texture builtin="flat" height="1278" mark="cross" markrgb="1 1 1" name="texgeom" random="0.01"
                 rgb1="0.8 0.6 0.4" rgb2="0.8 0.6 0.4" type="cube" width="127"/>
        <texture builtin="checker" height="100" name="texplane" rgb1="0 0 0" rgb2="0.8 0.8 0.8" type="2d" width="100"/>
        <material name="MatPlane" reflectance="0.5" shininess="1" specular="1" texrepeat="30 30" texture="texplane"/>
        <material name="geom" texture="texgeom" texuniform="true"/>
    </asset>
    <worldbody>
        <light cutoff="100" diffuse="1 1 1" dir="-0 0 -1.3" directional="true" exponent="1" pos="0 0 1.3"
               specular=".1 .1 .1"/>
        <geom conaffinity="1" condim="3" material="MatPlane" name="floor" pos="0 0 -0.1" rgba="0.8 0.9 0.8 1"
              size="4 4 0.01" type="plane"/>
        <!--  ================= SWIMMER ================= /-->

        <body name="torso" pos="0 0 0">
            <camera name="track" mode="trackcom" pos="-3 -15 15" xyaxes="1 0 0 0 1 1"/>
            <geom class="g"/>
            <joint axis="1 0 0" name="slider1" pos="0 0 0" type="slide" armature='0' stiffness="0" damping="0"/>
            <joint axis="0 1 0" name="slider2" pos="0 0 0" type="slide" armature='0' stiffness="0" damping="0"/>
            <joint axis="0 0 1" name="rot" pos="0 0 0" type="hinge" armature='0' stiffness="0" damping="0"/>
            <site name="head" class="mid"/>
            <site name="p1" pos="0 0 0" size="0.01"/>
            <body name="body1" pos="-.1 0 0">
                <geom class="g"/>
                <joint class="j" name="rot1"/>
                <site name="site1" class="mid"/>
                <site name="p2" class="joint_mark"/>
                <body name="body2" pos="-.1 0 0">
                    <geom class="g"/>
                    <joint class="j" name="rot2"/>
                    <site name="site2" class="mid"/>
                    <site class="joint_mark"/>
                    <body name="body3" pos="-.1 0 0">
                        <geom class="g"/>
                        <joint class="j" name="rot3"/>
                        <site name="site3" class="mid"/>
                        <site class="joint_mark"/>
                        <body name="body4" pos="-.1 0 0">
                            <geom class="g"/>
                            <joint class="j" name="rot4"/>
                            <site name="site4" class="mid"/>
                            <site class="joint_mark"/>
                            <body name="body5" pos="-.1 0 0">
                                <geom class="g"/>
                                <joint class="j" name="rot5"/>
                                <site name="site5" class="mid"/>
                                <site class="joint_mark"/>
                                <body name="body6" pos="-.1 0 0">
                                    <geom class="g"/>
                                    <joint class="j" name="rot6"/>
                                    <site name="site6" class="mid"/>
                                    <site name="p3" class="joint_mark"/>
                                    <site name="p4" pos="-0.1 0 0" size="0.01"/>
                                </body>
                            </body>
                        </body>
                    </body>
                </body>
            </body>
        </body>
    </worldbody>

    <sensor>
<!--        <gyro name="head_gyro" site="head"/>-->
        <gyro name="gyro1" site="site1"/>
        <gyro name="gyro2" site="site2"/>
        <gyro name="gyro3" site="site3"/>
        <gyro name="gyro4" site="site4"/>
        <gyro name="gyro5" site="site5"/>
        <gyro name="gyro6" site="site6"/>

        <framepos objtype="site" objname="head"/>
        <framepos objtype="site" objname="site1"/>
        <framepos objtype="site" objname="site2"/>
        <framepos objtype="site" objname="site3"/>
        <framepos objtype="site" objname="site4"/>
        <framepos objtype="site" objname="site5"/>
        <framepos objtype="site" objname="site6"/>
        <framepos objtype="site" objname="p1"/>
        <framepos objtype="site" objname="p2"/>
        <framepos objtype="site" objname="p3"/>
        <framepos objtype="site" objname="p4"/>

<!--        <torque name="joint1" site="site1"/>-->
<!--        <torque name="joint2" site="site2"/>-->
<!--        <torque name="joint3" site="site3"/>-->
<!--        <torque name="joint4" site="site4"/>-->
<!--        <torque name="joint5" site="site5"/>-->
<!--        <torque name="joint6" site="site6"/>-->

    </sensor>

    <actuator>
<!--        <position ctrllimited="true" ctrlrange="-1 1" forcelimited="true" forcerange="-0.1 0.1" kp="0.1" gear="1" joint="rot1"/>-->
<!--        <position ctrllimited="true" ctrlrange="-1 1" forcelimited="true" forcerange="-0.1 0.1" kp="0.1" gear="1" joint="rot2"/>-->
<!--        <position ctrllimited="true" ctrlrange="-1 1" forcelimited="true" forcerange="-0.1 0.1" kp="0.1" gear="1" joint="rot3"/>-->
<!--        <position ctrllimited="true" ctrlrange="-1 1" forcelimited="true" forcerange="-0.1 0.1" kp="0.1" gear="1" joint="rot4"/>-->
<!--        <position ctrllimited="true" ctrlrange="-1 1" forcelimited="true" forcerange="-0.1 0.1" kp="0.1" gear="1" joint="rot5"/>-->
<!--        <position ctrllimited="true" ctrlrange="-1 1" forcelimited="true" forcerange="-0.1 0.1" kp="0.1" gear="1" joint="rot6"/>-->
        <motor ctrllimited="true" ctrlrange="-1 1" forcelimited="true" forcerange="-1 1" gear="1" joint="rot1"/>
        <motor ctrllimited="true" ctrlrange="-1 1" forcelimited="true" forcerange="-1 1" gear="1" joint="rot2"/>
        <motor ctrllimited="true" ctrlrange="-1 1" forcelimited="true" forcerange="-1 1" gear="1" joint="rot3"/>
        <motor ctrllimited="true" ctrlrange="-1 1" forcelimited="true" forcerange="-1 1" gear="1" joint="rot4"/>
        <motor ctrllimited="true" ctrlrange="-1 1" forcelimited="true" forcerange="-1 1" gear="1" joint="rot5"/>
        <motor ctrllimited="true" ctrlrange="-1 1" forcelimited="true" forcerange="-1 1" gear="1" joint="rot6"/>
    </actuator>
</mujoco>
