<mujoco model="manta">
    <compiler angle="degree" coordinate="local" inertiafromgeom="true"/>
    <option collision="predefined" density="1000" integrator="RK4" timestep="0.01" viscosity="0.1"/>
    <default>
        <geom conaffinity="1" condim="1" contype="1" material="geom" rgba="0.8 0.6 .4 1"/>
        <joint armature='0.1'/>
        <default class="DEA_active">
            <geom type='box' size='.007 .0025 .0002' rgba='1 1 1 1'/>
        </default>
        <default class="DEA_passive">
            <geom type='box' size='.006 .0025 .0002' rgba='1 1 1 1'/>
        </default>
        <default class="left_joint_active">
            <joint axis="1 0 0" limited="true" pos="0 -0.0025 0" range="-1 1" type="hinge"/>
        </default>
        <default class="right_joint_active">
            <joint axis="1 0 0" limited="true" pos="0 0.0025 0" range="-1 1" type="hinge"/>
        </default>
        <default class="joint_passive">
            <joint axis="0 1 0" limited="true" pos=".006 0 0" range="-60 60" type="hinge"/>
        </default>
        <default class="endsite">
            <site pos="-0.005 0 0" size="0.0005"/>
        </default>
        <default class="headsite">
            <site pos="0.007 0 0" size="0.0005"/>
        </default>
        <default class="actuator">
            <motor ctrllimited="true" ctrlrange="-1 1" gear="150.0"/>
        </default>
    </default>
    <asset>
        <texture builtin="gradient" height="100" rgb1="1 1 1" rgb2="0 0 0" type="skybox" width="100"/>
        <texture builtin="flat" height="1278" mark="cross" markrgb="1 1 1" name="texgeom" random="0.01"
                 rgb1="0.8 0.6 0.4" rgb2="0.8 0.6 0.4" type="cube" width="127"/>
        <texture builtin="checker" height="100" name="texplane" rgb1="0 0 0" rgb2="0.8 0.8 0.8" type="2d" width="100"/>
        <material name="MatPlane" reflectance="0.5" shininess="1" specular="1" texrepeat="10 10" texture="texplane"/>
        <material name="geom" texture="texgeom" texuniform="true"/>
    </asset>
    <worldbody>
        <light cutoff="100" diffuse="1 1 1" dir="-0 0 -1.3" directional="true" exponent="1" pos="0 0 1.3"
               specular=".1 .1 .1"/>
        <geom conaffinity="1" condim="3" material="MatPlane" name="floor" pos="0 0 -0.1" rgba="0.8 0.9 0.8 1"
              size="1 1 0.1" type="plane"/>
        <!--  ======================================================================== torso ============================================================================= /-->
        <body name="torso" pos="0 0 .03">
            <camera name="track" mode="trackcom" pos="0 -3 3" xyaxes="1 0 0 0 1 1"/>
            <geom type='box' size='.05 .04 .02' rgba='.5 .5 1 1'/>
            <joint axis="1 0 0" name="slider1" pos="0 0 0" type="slide"/>
            <joint axis="0 1 0" name="slider2" pos="0 0 0" type="slide"/>
            <joint axis="0 0 1" name="rot" pos="0 0 0" type="hinge"/>
            <!--  ======================================================================== torso ============================================================================= /-->
            <!--  ======================================================================== left-1 ============================================================================= /-->
            <body name="left_active_1_1" pos=".024 .0425 0">
                <geom class="DEA_active"/>
                <joint name="left_active_1_1" class="left_joint_active"/>
                <body name="left_passive_1_1" pos="-.013 0 0">
                    <geom class="DEA_passive"/>
                    <joint name="temp" class="joint_passive"/>
                    <site name="left_end_1_1" class="endsite"/>
                </body>
                <body name="left_active_1_2" pos="0 .005 0">
                    <geom class="DEA_active"/>
                    <joint name="left_active_1_2" class="left_joint_active"/>
                    <body name="left_passive_1_2" pos="-.013 0 0">
                        <geom class="DEA_passive"/>
                        <joint class="joint_passive"/>
                        <site name="left_end_1_2" class="endsite"/>
                    </body>
                    <body name="left_active_1_3" pos="0 .005 0">
                        <geom class="DEA_active"/>
                        <joint name="left_active_1_3" class="left_joint_active"/>
                        <body name="left_passive_1_3" pos="-.013 0 0">
                            <geom class="DEA_passive"/>
                            <joint class="joint_passive"/>
                            <site name="left_end_1_3" class="endsite"/>
                        </body>
                        <body name="left_active_1_4" pos="0 .005 0">
                            <geom class="DEA_active"/>
                            <joint name="left_active_1_4" class="left_joint_active"/>
                            <body name="left_passive_1_4" pos="-.013 0 0">
                                <geom class="DEA_passive"/>
                                <joint class="joint_passive"/>
                                <site name="left_end_1_4" class="endsite"/>
                            </body>
                            <body name="left_active_1_5" pos="0 .005 0">
                                <geom class="DEA_active"/>
                                <joint name="left_active_1_5" class="left_joint_active"/>
                                <body name="left_passive_1_5" pos="-.013 0 0">
                                    <geom class="DEA_passive"/>
                                    <joint class="joint_passive"/>
                                    <site name="left_end_1_5" class="endsite"/>
                                </body>
                                <body name="left_active_1_6" pos="0 .005 0">
                                    <geom class="DEA_active"/>
                                    <joint name="left_active_1_6" class="left_joint_active"/>
                                    <body name="left_passive_1_6" pos="-.013 0 0">
                                        <geom class="DEA_passive"/>
                                        <joint class="joint_passive"/>
                                        <site name="left_end_1_6" class="endsite"/>
                                    </body>
                                    <body name="left_active_1_7" pos="0 .005 0">
                                        <geom class="DEA_active"/>
                                        <joint name="left_active_1_7" class="left_joint_active"/>
                                        <body name="left_passive_1_7" pos="-.013 0 0">
                                            <geom class="DEA_passive"/>
                                            <joint class="joint_passive"/>
                                            <site name="left_end_1_7" class="endsite"/>
                                        </body>
                                        <body name="left_active_1_8" pos="0 .005 0">
                                            <geom class="DEA_active"/>
                                            <joint name="left_active_1_8" class="left_joint_active"/>
                                            <body name="left_passive_1_8" pos="-.013 0 0">
                                                <geom class="DEA_passive"/>
                                                <joint class="joint_passive"/>
                                                <site name="left_end_1_8" class="endsite"/>
                                            </body>
                                            <body name="left_active_1_9" pos="0 .005 0">
                                                <geom class="DEA_active"/>
                                                <joint name="left_active_1_9" class="left_joint_active"/>
                                                <body name="left_passive_1_9" pos="-.013 0 0">
                                                    <geom class="DEA_passive"/>
                                                    <joint class="joint_passive"/>
                                                    <site name="left_end_1_9" class="endsite"/>
                                                </body>
                                                <body name="left_active_1_10" pos="0 .005 0">
                                                    <geom class="DEA_active"/>
                                                    <joint name="left_active_1_10" class="left_joint_active"/>
                                                    <body name="left_passive_1_10" pos="-.013 0 0">
                                                        <geom class="DEA_passive"/>
                                                        <joint class="joint_passive"/>
                                                        <site name="left_end_1_10" class="endsite"/>
                                                    </body>
                                                </body>
                                            </body>
                                        </body>
                                    </body>
                                </body>
                            </body>
                        </body>
                    </body>
                </body>
            </body>
            <!--  ======================================================================== left-1 ============================================================================= /-->
            <!--  ======================================================================== left-2 ============================================================================= /-->
            <body name="left_active_2_1" pos="0 .0425 0">
                <geom class="DEA_active"/>
                <joint name="left_active_2_1" class="left_joint_active"/>
                <site name="left_head_2_1" class="headsite"/>
                <body name="left_passive_2_1" pos="-.013 0 0">
                    <geom class="DEA_passive"/>
                    <joint class="joint_passive"/>
                    <site name="left_end_2_1" class="endsite"/>
                </body>
                <body name="left_active_2_2" pos="0 .005 0">
                    <geom class="DEA_active"/>
                    <joint name="left_active_2_2" class="left_joint_active"/>
                    <site name="left_head_2_2" class="headsite"/>
                    <body name="left_passive_2_2" pos="-.013 0 0">
                        <geom class="DEA_passive"/>
                        <joint class="joint_passive"/>
                        <site name="left_end_2_2" class="endsite"/>
                    </body>
                    <body name="left_active_2_3" pos="0 .005 0">
                        <geom class="DEA_active"/>
                        <joint name="left_active_2_3" class="left_joint_active"/>
                        <site name="left_head_2_3" class="headsite"/>
                        <body name="left_passive_2_3" pos="-.013 0 0">
                            <geom class="DEA_passive"/>
                            <joint class="joint_passive"/>
                            <site name="left_end_2_3" class="endsite"/>
                        </body>
                        <body name="left_active_2_4" pos="0 .005 0">
                            <geom class="DEA_active"/>
                            <joint name="left_active_2_4" class="left_joint_active"/>
                            <site name="left_head_2_4" class="headsite"/>
                            <body name="left_passive_2_4" pos="-.013 0 0">
                                <geom class="DEA_passive"/>
                                <joint class="joint_passive"/>
                                <site name="left_end_2_4" class="endsite"/>
                            </body>
                            <body name="left_active_2_5" pos="0 .005 0">
                                <geom class="DEA_active"/>
                                <joint name="left_active_2_5" class="left_joint_active"/>
                                <site name="left_head_2_5" class="headsite"/>
                                <body name="left_passive_2_5" pos="-.013 0 0">
                                    <geom class="DEA_passive"/>
                                    <joint class="joint_passive"/>
                                    <site name="left_end_2_5" class="endsite"/>
                                </body>
                                <body name="left_active_2_6" pos="0 .005 0">
                                    <geom class="DEA_active"/>
                                    <joint name="left_active_2_6" class="left_joint_active"/>
                                    <site name="left_head_2_6" class="headsite"/>
                                    <body name="left_passive_2_6" pos="-.013 0 0">
                                        <geom class="DEA_passive"/>
                                        <joint class="joint_passive"/>
                                        <site name="left_end_2_6" class="endsite"/>
                                    </body>
                                    <body name="left_active_2_7" pos="0 .005 0">
                                        <geom class="DEA_active"/>
                                        <joint name="left_active_2_7" class="left_joint_active"/>
                                        <site name="left_head_2_7" class="headsite"/>
                                        <body name="left_passive_2_7" pos="-.013 0 0">
                                            <geom class="DEA_passive"/>
                                            <joint class="joint_passive"/>
                                            <site name="left_end_2_7" class="endsite"/>
                                        </body>
                                        <body name="left_active_2_8" pos="0 .005 0">
                                            <geom class="DEA_active"/>
                                            <joint name="left_active_2_8" class="left_joint_active"/>
                                            <site name="left_head_2_8" class="headsite"/>
                                            <body name="left_passive_2_8" pos="-.013 0 0">
                                                <geom class="DEA_passive"/>
                                                <joint class="joint_passive"/>
                                                <site name="left_end_2_8" class="endsite"/>
                                            </body>
                                            <body name="left_active_2_9" pos="0 .005 0">
                                                <geom class="DEA_active"/>
                                                <joint name="left_active_2_9" class="left_joint_active"/>
                                                <site name="left_head_2_9" class="headsite"/>
                                                <body name="left_passive_2_9" pos="-.013 0 0">
                                                    <geom class="DEA_passive"/>
                                                    <joint class="joint_passive"/>
                                                    <site name="left_end_2_9" class="endsite"/>
                                                </body>
                                                <body name="left_active_2_10" pos="0 .005 0">
                                                    <geom class="DEA_active"/>
                                                    <joint name="left_active_2_10" class="left_joint_active"/>
                                                    <site name="left_head_2_10" class="headsite"/>
                                                    <body name="left_passive_2_10" pos="-.013 0 0">
                                                        <geom class="DEA_passive"/>
                                                        <joint class="joint_passive"/>
                                                        <site name="left_end_2_10" class="endsite"/>
                                                    </body>
                                                </body>
                                            </body>
                                        </body>
                                    </body>
                                </body>
                            </body>
                        </body>
                    </body>
                </body>
            </body>
            <!--  ======================================================================== left-2 ============================================================================= /-->
            <!--  ======================================================================== left-3 ============================================================================= /-->
            <body name="left_active_3_1" pos="-.024 .0425 0">
                <geom class="DEA_active"/>
                <joint name="left_active_3_1" class="left_joint_active"/>
                <site name="left_head_3_1" class="headsite"/>
                <body name="left_active_3_2" pos="0 .005 0">
                    <geom class="DEA_active"/>
                    <joint name="left_active_3_2" class="left_joint_active"/>
                    <site name="left_head_3_2" class="headsite"/>
                    <body name="left_active_3_3" pos="0 .005 0">
                        <geom class="DEA_active"/>
                        <joint name="left_active_3_3" class="left_joint_active"/>
                        <site name="left_head_3_3" class="headsite"/>
                        <body name="left_active_3_4" pos="0 .005 0">
                            <geom class="DEA_active"/>
                            <joint name="left_active_3_4" class="left_joint_active"/>
                            <site name="left_head_3_4" class="headsite"/>
                            <body name="left_active_3_5" pos="0 .005 0">
                                <geom class="DEA_active"/>
                                <joint name="left_active_3_5" class="left_joint_active"/>
                                <site name="left_head_3_5" class="headsite"/>
                                <body name="left_active_3_6" pos="0 .005 0">
                                    <geom class="DEA_active"/>
                                    <joint name="left_active_3_6" class="left_joint_active"/>
                                    <site name="left_head_3_6" class="headsite"/>
                                    <body name="left_active_3_7" pos="0 .005 0">
                                        <geom class="DEA_active"/>
                                        <joint name="left_active_3_7" class="left_joint_active"/>
                                        <site name="left_head_3_7" class="headsite"/>
                                        <body name="left_active_3_8" pos="0 .005 0">
                                            <geom class="DEA_active"/>
                                            <joint name="left_active_3_8" class="left_joint_active"/>
                                            <site name="left_head_3_8" class="headsite"/>
                                            <body name="left_active_3_9" pos="0 .005 0">
                                                <geom class="DEA_active"/>
                                                <joint name="left_active_3_9" class="left_joint_active"/>
                                                <site name="left_head_3_9" class="headsite"/>
                                                <body name="left_active_3_10" pos="0 .005 0">
                                                    <geom class="DEA_active"/>
                                                    <joint name="left_active_3_10" class="left_joint_active"/>
                                                    <site name="left_head_3_10" class="headsite"/>
                                                </body>
                                            </body>
                                        </body>
                                    </body>
                                </body>
                            </body>
                        </body>
                    </body>
                </body>
            </body>

            <!--  ======================================================================== left-3 ============================================================================= /-->
            <!--  ======================================================================== right-1 ============================================================================= /-->
            <body name="right_active_1_1" pos=".024 -.0425 0">
                <geom class="DEA_active"/>
                <joint name="right_active_1_1" class="right_joint_active"/>
                <body name="right_passive_1_1" pos="-.012 0 0">
                    <geom class="DEA_passive"/>
                    <joint class="joint_passive"/>
                    <site name="right_end_1_1" class="endsite"/>
                </body>
                <body name="right_active_1_2" pos="0 -.005 0">
                    <geom class="DEA_active"/>
                    <joint name="right_active_1_2" class="right_joint_active"/>
                    <body name="right_passive_1_2" pos="-.012 0 0">
                        <geom class="DEA_passive"/>
                        <joint class="joint_passive"/>
                        <site name="right_end_1_2" class="endsite"/>
                    </body>
                    <body name="right_active_1_3" pos="0 -.005 0">
                        <geom class="DEA_active"/>
                        <joint name="right_active_1_3" class="right_joint_active"/>
                        <body name="right_passive_1_3" pos="-.012 0 0">
                            <geom class="DEA_passive"/>
                            <joint class="joint_passive"/>
                            <site name="right_end_1_3" class="endsite"/>
                        </body>
                        <body name="right_active_1_4" pos="0 -.005 0">
                            <geom class="DEA_active"/>
                            <joint name="right_active_1_4" class="right_joint_active"/>
                            <body name="right_passive_1_4" pos="-.012 0 0">
                                <geom class="DEA_passive"/>
                                <joint class="joint_passive"/>
                                <site name="right_end_1_4" class="endsite"/>
                            </body>
                            <body name="right_active_1_5" pos="0 -.005 0">
                                <geom class="DEA_active"/>
                                <joint name="right_active_1_5" class="right_joint_active"/>
                                <body name="right_passive_1_5" pos="-.012 0 0">
                                    <geom class="DEA_passive"/>
                                    <joint class="joint_passive"/>
                                    <site name="right_end_1_5" class="endsite"/>
                                </body>
                                <body name="right_active_1_6" pos="0 -.005 0">
                                    <geom class="DEA_active"/>
                                    <joint name="right_active_1_6" class="right_joint_active"/>
                                    <body name="right_passive_1_6" pos="-.012 0 0">
                                        <geom class="DEA_passive"/>
                                        <joint class="joint_passive"/>
                                        <site name="right_end_1_6" class="endsite"/>
                                    </body>
                                    <body name="right_active_1_7" pos="0 -.005 0">
                                        <geom class="DEA_active"/>
                                        <joint name="right_active_1_7" class="right_joint_active"/>
                                        <body name="right_passive_1_7" pos="-.012 0 0">
                                            <geom class="DEA_passive"/>
                                            <joint class="joint_passive"/>
                                            <site name="right_end_1_7" class="endsite"/>
                                        </body>
                                        <body name="right_active_1_8" pos="0 -.005 0">
                                            <geom class="DEA_active"/>
                                            <joint name="right_active_1_8" class="right_joint_active"/>
                                            <body name="right_passive_1_8" pos="-.012 0 0">
                                                <geom class="DEA_passive"/>
                                                <joint class="joint_passive"/>
                                                <site name="right_end_1_8" class="endsite"/>
                                            </body>
                                            <body name="right_active_1_9" pos="0 -.005 0">
                                                <geom class="DEA_active"/>
                                                <joint name="right_active_1_9" class="right_joint_active"/>
                                                <body name="right_passive_1_9" pos="-.012 0 0">
                                                    <geom class="DEA_passive"/>
                                                    <joint class="joint_passive"/>
                                                    <site name="right_end_1_9" class="endsite"/>
                                                </body>
                                                <body name="right_active_1_10" pos="0 -.005 0">
                                                    <geom class="DEA_active"/>
                                                    <joint name="right_active_1_10" class="right_joint_active"/>
                                                    <body name="right_passive_1_10" pos="-.012 0 0">
                                                        <geom class="DEA_passive"/>
                                                        <joint class="joint_passive"/>
                                                        <site name="right_end_1_10" class="endsite"/>
                                                    </body>
                                                </body>
                                            </body>
                                        </body>
                                    </body>
                                </body>
                            </body>
                        </body>
                    </body>
                </body>
            </body>
            <!--  ======================================================================== right-1 ============================================================================= /-->
            <!--  ======================================================================== right-2 ============================================================================= /-->
            <body name="right_active_2_1" pos="0 -.0425 0">
                <geom class="DEA_active"/>
                <joint name="right_active_2_1" class="right_joint_active"/>
                <site name="right_head_2_1" class="headsite"/>
                <body name="right_passive_2_1" pos="-.012 0 0">
                    <geom class="DEA_passive"/>
                    <joint class="joint_passive"/>
                    <site name="right_end_2_1" class="endsite"/>
                </body>
                <body name="right_active_2_2" pos="0 -.005 0">
                    <geom class="DEA_active"/>
                    <joint name="right_active_2_2" class="right_joint_active"/>
                    <site name="right_head_2_2" class="headsite"/>
                    <body name="right_passive_2_2" pos="-.012 0 0">
                        <geom class="DEA_passive"/>
                        <joint class="joint_passive"/>
                        <site name="right_end_2_2" class="endsite"/>
                    </body>
                    <body name="right_active_2_3" pos="0 -.005 0">
                        <geom class="DEA_active"/>
                        <joint name="right_active_2_3" class="right_joint_active"/>
                        <site name="right_head_2_3" class="headsite"/>
                        <body name="right_passive_2_3" pos="-.012 0 0">
                            <geom class="DEA_passive"/>
                            <joint class="joint_passive"/>
                            <site name="right_end_2_3" class="endsite"/>
                        </body>
                        <body name="right_active_2_4" pos="0 -.005 0">
                            <geom class="DEA_active"/>
                            <joint name="right_active_2_4" class="right_joint_active"/>
                            <site name="right_head_2_4" class="headsite"/>
                            <body name="right_passive_2_4" pos="-.012 0 0">
                                <geom class="DEA_passive"/>
                                <joint class="joint_passive"/>
                                <site name="right_end_2_4" class="endsite"/>
                            </body>
                            <body name="right_active_2_5" pos="0 -.005 0">
                                <geom class="DEA_active"/>
                                <joint name="right_active_2_5" class="right_joint_active"/>
                                <site name="right_head_2_5" class="headsite"/>
                                <body name="right_passive_2_5" pos="-.012 0 0">
                                    <geom class="DEA_passive"/>
                                    <joint class="joint_passive"/>
                                    <site name="right_end_2_5" class="endsite"/>
                                </body>
                                <body name="right_active_2_6" pos="0 -.005 0">
                                    <geom class="DEA_active"/>
                                    <joint name="right_active_2_6" class="right_joint_active"/>
                                    <site name="right_head_2_6" class="headsite"/>
                                    <body name="right_passive_2_6" pos="-.012 0 0">
                                        <geom class="DEA_passive"/>
                                        <joint class="joint_passive"/>
                                        <site name="right_end_2_6" class="endsite"/>
                                    </body>
                                    <body name="right_active_2_7" pos="0 -.005 0">
                                        <geom class="DEA_active"/>
                                        <joint name="right_active_2_7" class="right_joint_active"/>
                                        <site name="right_head_2_7" class="headsite"/>
                                        <body name="right_passive_2_7" pos="-.012 0 0">
                                            <geom class="DEA_passive"/>
                                            <joint class="joint_passive"/>
                                            <site name="right_end_2_7" class="endsite"/>
                                        </body>
                                        <body name="right_active_2_8" pos="0 -.005 0">
                                            <geom class="DEA_active"/>
                                            <joint name="right_active_2_8" class="right_joint_active"/>
                                            <site name="right_head_2_8" class="headsite"/>
                                            <body name="right_passive_2_8" pos="-.012 0 0">
                                                <geom class="DEA_passive"/>
                                                <joint class="joint_passive"/>
                                                <site name="right_end_2_8" class="endsite"/>
                                            </body>
                                            <body name="right_active_2_9" pos="0 -.005 0">
                                                <geom class="DEA_active"/>
                                                <joint name="right_active_2_9" class="right_joint_active"/>
                                                <site name="right_head_2_9" class="headsite"/>
                                                <body name="right_passive_2_9" pos="-.012 0 0">
                                                    <geom class="DEA_passive"/>
                                                    <joint class="joint_passive"/>
                                                    <site name="right_end_2_9" class="endsite"/>
                                                </body>
                                                <body name="right_active_2_10" pos="0 -.005 0">
                                                    <geom class="DEA_active"/>
                                                    <joint name="right_active_2_10" class="right_joint_active"/>
                                                    <site name="right_head_2_10" class="headsite"/>
                                                    <body name="right_passive_2_10" pos="-.012 0 0">
                                                        <geom class="DEA_passive"/>
                                                        <joint class="joint_passive"/>
                                                        <site name="right_end_2_10" class="endsite"/>
                                                    </body>
                                                </body>
                                            </body>
                                        </body>
                                    </body>
                                </body>
                            </body>
                        </body>
                    </body>
                </body>
            </body>
            <!--  ======================================================================== right-2 ============================================================================= /-->
            <!--  ======================================================================== right-3 ============================================================================= /-->
            <body name="right_active_3_1" pos="-.024 -.0425 0">
                <geom class="DEA_active"/>
                <joint name="right_active_3_1" class="right_joint_active"/>
                <site name="right_head_3_1" class="headsite"/>
                <body name="right_active_3_2" pos="0 -.005 0">
                    <geom class="DEA_active"/>
                    <joint name="right_active_3_2" class="right_joint_active"/>
                    <site name="right_head_3_2" class="headsite"/>
                    <body name="right_active_3_3" pos="0 -.005 0">
                        <geom class="DEA_active"/>
                        <joint name="right_active_3_3" class="right_joint_active"/>
                        <site name="right_head_3_3" class="headsite"/>
                        <body name="right_active_3_4" pos="0 -.005 0">
                            <geom class="DEA_active"/>
                            <joint name="right_active_3_4" class="right_joint_active"/>
                            <site name="right_head_3_4" class="headsite"/>
                            <body name="right_active_3_5" pos="0 -.005 0">
                                <geom class="DEA_active"/>
                                <joint name="right_active_3_5" class="right_joint_active"/>
                                <site name="right_head_3_5" class="headsite"/>
                                <body name="right_active_3_6" pos="0 -.005 0">
                                    <geom class="DEA_active"/>
                                    <joint name="right_active_3_6" class="right_joint_active"/>
                                    <site name="right_head_3_6" class="headsite"/>
                                    <body name="right_active_3_7" pos="0 -.005 0">
                                        <geom class="DEA_active"/>
                                        <joint name="right_active_3_7" class="right_joint_active"/>
                                        <site name="right_head_3_7" class="headsite"/>
                                        <body name="right_active_3_8" pos="0 -.005 0">
                                            <geom class="DEA_active"/>
                                            <joint name="right_active_3_8" class="right_joint_active"/>
                                            <site name="right_head_3_8" class="headsite"/>
                                            <body name="right_active_3_9" pos="0 -.005 0">
                                                <geom class="DEA_active"/>
                                                <joint name="right_active_3_9" class="right_joint_active"/>
                                                <site name="right_head_3_9" class="headsite"/>
                                                <body name="right_active_3_10" pos="0 -.005 0">
                                                    <geom class="DEA_active"/>
                                                    <joint name="right_active_3_10" class="right_joint_active"/>
                                                    <site name="right_head_3_10" class="headsite"/>
                                                </body>
                                            </body>
                                        </body>
                                    </body>
                                </body>
                            </body>
                        </body>
                    </body>
                </body>
            </body>
            <!--  ======================================================================== right-3 ============================================================================= /-->
        </body>
    </worldbody>
    <!--    add tendon from one site to another site-->
    <tendon>
        <!-- ================================================= left 1 - 2 ====================================================-->
        <spatial width="0.0001" stiffness="500">
            <site site="left_end_1_1"/>
            <site site="left_head_2_1"/>
        </spatial>
        <spatial width="0.0001" stiffness="500">
            <site site="left_end_1_2"/>
            <site site="left_head_2_2"/>
        </spatial>
        <spatial width="0.0001" stiffness="500">
            <site site="left_end_1_3"/>
            <site site="left_head_2_3"/>
        </spatial>
        <spatial width="0.0001" stiffness="500">
            <site site="left_end_1_4"/>
            <site site="left_head_2_4"/>
        </spatial>
        <spatial width="0.0001" stiffness="500">
            <site site="left_end_1_5"/>
            <site site="left_head_2_5"/>
        </spatial>
        <spatial width="0.0001" stiffness="500">
            <site site="left_end_1_6"/>
            <site site="left_head_2_6"/>
        </spatial>
        <spatial width="0.0001" stiffness="500">
            <site site="left_end_1_7"/>
            <site site="left_head_2_7"/>
        </spatial>
        <spatial width="0.0001" stiffness="500">
            <site site="left_end_1_8"/>
            <site site="left_head_2_8"/>
        </spatial>
        <spatial width="0.0001" stiffness="500">
            <site site="left_end_1_9"/>
            <site site="left_head_2_9"/>
        </spatial>
        <spatial width="0.0001" stiffness="500">
            <site site="left_end_1_10"/>
            <site site="left_head_2_10"/>
        </spatial>
        <!-- ================================================= left 1 - 2 ====================================================-->
        <!-- ================================================= left 2 - 3 ====================================================-->
        <spatial width="0.0001" stiffness="100">
            <site site="left_end_2_1"/>
            <site site="left_head_3_1"/>
        </spatial>
        <spatial width="0.0001" stiffness="100">
            <site site="left_end_2_2"/>
            <site site="left_head_3_2"/>
        </spatial>
        <spatial width="0.0001" stiffness="100">
            <site site="left_end_2_3"/>
            <site site="left_head_3_3"/>
        </spatial>
        <spatial width="0.0001" stiffness="100">
            <site site="left_end_2_4"/>
            <site site="left_head_3_4"/>
        </spatial>
        <spatial width="0.0001" stiffness="100">
            <site site="left_end_2_5"/>
            <site site="left_head_3_5"/>
        </spatial>
        <spatial width="0.0001" stiffness="100">
            <site site="left_end_2_6"/>
            <site site="left_head_3_6"/>
        </spatial>
        <spatial width="0.0001" stiffness="100">
            <site site="left_end_2_7"/>
            <site site="left_head_3_7"/>
        </spatial>
        <spatial width="0.0001" stiffness="100">
            <site site="left_end_2_8"/>
            <site site="left_head_3_8"/>
        </spatial>
        <spatial width="0.0001" stiffness="100">
            <site site="left_end_2_9"/>
            <site site="left_head_3_9"/>
        </spatial>
        <spatial width="0.0001" stiffness="100">
            <site site="left_end_2_10"/>
            <site site="left_head_3_10"/>
        </spatial>
        <!-- ================================================= left 2 - 3 ====================================================-->

        <!-- ================================================= right 1 - 2 ====================================================-->
        <spatial width="0.0001" stiffness="100">
            <site site="right_end_1_1"/>
            <site site="right_head_2_1"/>
        </spatial>
        <spatial width="0.0001" stiffness="100">
            <site site="right_end_1_2"/>
            <site site="right_head_2_2"/>
        </spatial>
        <spatial width="0.0001" stiffness="100">
            <site site="right_end_1_3"/>
            <site site="right_head_2_3"/>
        </spatial>
        <spatial width="0.0001" stiffness="100">
            <site site="right_end_1_4"/>
            <site site="right_head_2_4"/>
        </spatial>
        <spatial width="0.0001" stiffness="100">
            <site site="right_end_1_5"/>
            <site site="right_head_2_5"/>
        </spatial>
        <spatial width="0.0001" stiffness="100">
            <site site="right_end_1_6"/>
            <site site="right_head_2_6"/>
        </spatial>
        <spatial width="0.0001" stiffness="100">
            <site site="right_end_1_7"/>
            <site site="right_head_2_7"/>
        </spatial>
        <spatial width="0.0001" stiffness="100">
            <site site="right_end_1_8"/>
            <site site="right_head_2_8"/>
        </spatial>
        <spatial width="0.0001" stiffness="100">
            <site site="right_end_1_9"/>
            <site site="right_head_2_9"/>
        </spatial>
        <spatial width="0.0001" stiffness="100">
            <site site="right_end_1_10"/>
            <site site="right_head_2_10"/>
        </spatial>
        <!-- ================================================= right 1 - 2 ====================================================-->
        <!-- ================================================= right 2 - 3 ====================================================-->
        <spatial width="0.0001" stiffness="100">
            <site site="right_end_2_1"/>
            <site site="right_head_3_1"/>
        </spatial>
        <spatial width="0.0001" stiffness="100">
            <site site="right_end_2_2"/>
            <site site="right_head_3_2"/>
        </spatial>
        <spatial width="0.0001" stiffness="100">
            <site site="right_end_2_3"/>
            <site site="right_head_3_3"/>
        </spatial>
        <spatial width="0.0001" stiffness="100">
            <site site="right_end_2_4"/>
            <site site="right_head_3_4"/>
        </spatial>
        <spatial width="0.0001" stiffness="100">
            <site site="right_end_2_5"/>
            <site site="right_head_3_5"/>
        </spatial>
        <spatial width="0.0001" stiffness="100">
            <site site="right_end_2_6"/>
            <site site="right_head_3_6"/>
        </spatial>
        <spatial width="0.0001" stiffness="100">
            <site site="right_end_2_7"/>
            <site site="right_head_3_7"/>
        </spatial>
        <spatial width="0.0001" stiffness="100">
            <site site="right_end_2_8"/>
            <site site="right_head_3_8"/>
        </spatial>
        <spatial width="0.0001" stiffness="100">
            <site site="right_end_2_9"/>
            <site site="right_head_3_9"/>
        </spatial>
        <spatial width="0.0001" stiffness="100">
            <site site="right_end_2_10"/>
            <site site="right_head_3_10"/>
        </spatial>
        <!-- ================================================= right 2 - 3 ====================================================-->

    </tendon>

    <actuator>
        <motor class="actuator" joint="left_active_1_1"/>
        <!--        <motor class="actuator" joint="temp"/>-->
        <motor class="actuator" joint="left_active_1_2"/>
        <motor class="actuator" joint="left_active_1_3"/>
        <motor class="actuator" joint="left_active_1_4"/>
        <motor class="actuator" joint="left_active_1_5"/>
        <motor class="actuator" joint="left_active_1_6"/>
        <motor class="actuator" joint="left_active_1_7"/>
        <motor class="actuator" joint="left_active_1_8"/>
        <motor class="actuator" joint="left_active_1_9"/>
        <motor class="actuator" joint="left_active_1_10"/>

        <motor class="actuator" joint="left_active_2_1"/>
        <motor class="actuator" joint="left_active_2_2"/>
        <motor class="actuator" joint="left_active_2_3"/>
        <motor class="actuator" joint="left_active_2_4"/>
        <motor class="actuator" joint="left_active_2_5"/>
        <motor class="actuator" joint="left_active_2_6"/>
        <motor class="actuator" joint="left_active_2_7"/>
        <motor class="actuator" joint="left_active_2_8"/>
        <motor class="actuator" joint="left_active_2_9"/>
        <motor class="actuator" joint="left_active_2_10"/>

        <motor class="actuator" joint="left_active_3_1"/>
        <motor class="actuator" joint="left_active_3_2"/>
        <motor class="actuator" joint="left_active_3_3"/>
        <motor class="actuator" joint="left_active_3_4"/>
        <motor class="actuator" joint="left_active_3_5"/>
        <motor class="actuator" joint="left_active_3_6"/>
        <motor class="actuator" joint="left_active_3_7"/>
        <motor class="actuator" joint="left_active_3_8"/>
        <motor class="actuator" joint="left_active_3_9"/>
        <motor class="actuator" joint="left_active_3_10"/>

        <motor class="actuator" joint="right_active_1_1"/>
        <motor class="actuator" joint="right_active_1_2"/>
        <motor class="actuator" joint="right_active_1_3"/>
        <motor class="actuator" joint="right_active_1_4"/>
        <motor class="actuator" joint="right_active_1_5"/>
        <motor class="actuator" joint="right_active_1_6"/>
        <motor class="actuator" joint="right_active_1_7"/>
        <motor class="actuator" joint="right_active_1_8"/>
        <motor class="actuator" joint="right_active_1_9"/>
        <motor class="actuator" joint="right_active_1_10"/>

        <motor class="actuator" joint="right_active_2_1"/>
        <motor class="actuator" joint="right_active_2_2"/>
        <motor class="actuator" joint="right_active_2_3"/>
        <motor class="actuator" joint="right_active_2_4"/>
        <motor class="actuator" joint="right_active_2_5"/>
        <motor class="actuator" joint="right_active_2_6"/>
        <motor class="actuator" joint="right_active_2_7"/>
        <motor class="actuator" joint="right_active_2_8"/>
        <motor class="actuator" joint="right_active_2_9"/>
        <motor class="actuator" joint="right_active_2_10"/>

        <motor class="actuator" joint="right_active_3_1"/>
        <motor class="actuator" joint="right_active_3_2"/>
        <motor class="actuator" joint="right_active_3_3"/>
        <motor class="actuator" joint="right_active_3_4"/>
        <motor class="actuator" joint="right_active_3_5"/>
        <motor class="actuator" joint="right_active_3_6"/>
        <motor class="actuator" joint="right_active_3_7"/>
        <motor class="actuator" joint="right_active_3_8"/>
        <motor class="actuator" joint="right_active_3_9"/>
        <motor class="actuator" joint="right_active_3_10"/>
    </actuator>
</mujoco>
